{
 "cells": [
  {
   "cell_type": "code",
   "execution_count": 45,
   "metadata": {},
   "outputs": [],
   "source": [
    "import numpy as np\n",
    "import tensorflow as tf\n",
    "from tensorflow.keras.preprocessing.image import ImageDataGenerator\n",
    "from skimage.io import imread"
   ]
  },
  {
   "cell_type": "code",
   "execution_count": 46,
   "metadata": {},
   "outputs": [
    {
     "name": "stderr",
     "output_type": "stream",
     "text": [
      "/tmp/ipykernel_160003/903680710.py:5: UserWarning: `input_shape` is undefined or non-square, or `rows` is not in [96, 128, 160, 192, 224]. Weights for input shape (224, 224) will be loaded as the default.\n",
      "  base_model = MobileNetV2(weights='imagenet', include_top=False, input_shape=(640, 800, 3))\n"
     ]
    }
   ],
   "source": [
    "from tensorflow.keras.applications import MobileNetV2\n",
    "from tensorflow.keras.models import Model\n",
    "from tensorflow.keras.layers import Dense, GlobalAveragePooling2D, Conv2D, UpSampling2D\n",
    "\n",
    "base_model = MobileNetV2(weights='imagenet', include_top=False, input_shape=(640, 800, 3))\n",
    "classes = 1\n",
    "\n",
    "x = base_model.output\n",
    "x = Conv2D(256, (3, 3), activation='relu', padding='same')(x)\n",
    "x = UpSampling2D((2, 2))(x)\n",
    "x = Conv2D(128, (3, 3), activation='relu', padding='same')(x)\n",
    "x = UpSampling2D((2, 2))(x)\n",
    "x = Conv2D(64, (3, 3), activation='relu', padding='same')(x)\n",
    "x = UpSampling2D((2, 2))(x)\n",
    "x = Conv2D(32, (3, 3), activation='relu', padding='same')(x)\n",
    "x = UpSampling2D((2, 2))(x)\n",
    "x = Conv2D(16, (3, 3), activation='relu', padding='same')(x)\n",
    "x = UpSampling2D((2, 2))(x)\n",
    "output = Conv2D(1, (1, 1), activation='sigmoid', padding='same')(x)\n",
    "\n",
    "\n",
    "model = Model(inputs=base_model.input, outputs=output)\n",
    "\n"
   ]
  },
  {
   "cell_type": "markdown",
   "metadata": {},
   "source": [
    "### Data Augmentation and Training"
   ]
  },
  {
   "cell_type": "code",
   "execution_count": 47,
   "metadata": {},
   "outputs": [
    {
     "data": {
      "text/plain": [
       "(131,)"
      ]
     },
     "execution_count": 47,
     "metadata": {},
     "output_type": "execute_result"
    }
   ],
   "source": [
    "#get image and mask paths\n",
    "#convert to dataframe\n",
    "import pandas as pd\n",
    "import os\n",
    "df = pd.read_csv('data/640x800/640x800.csv')\n",
    "\n",
    "image_paths = np.array(df['snow_path'].values)\n",
    "mask_paths = np.array(df['snowbinary_path'].values)\n",
    "image_paths.shape\n"
   ]
  },
  {
   "cell_type": "code",
   "execution_count": 48,
   "metadata": {},
   "outputs": [],
   "source": [
    "\n",
    "def load_data(image_paths, mask_paths):\n",
    "    images = [imread(img_path) for img_path in image_paths]\n",
    "    masks = [imread(mask_path) for mask_path in mask_paths]\n",
    "    \n",
    "    #resize all images with 4 channels to 3 channels\n",
    "    for i in range(len(images)):\n",
    "        if(len(images[i][0][0])==4):\n",
    "            images[i] = images[i][:,:,:3]\n",
    "\n",
    "    #resize all masks to 1120x640\n",
    "    for i in range(len(masks)):\n",
    "        masks[i] = masks[i][:800,:640]\n",
    "    \n",
    "    \n",
    "    return np.array(images), np.array(masks)\n",
    "\n",
    "images, masks = load_data(image_paths, mask_paths)"
   ]
  },
  {
   "cell_type": "code",
   "execution_count": 49,
   "metadata": {},
   "outputs": [
    {
     "data": {
      "text/plain": [
       "(131, 800, 640, 1)"
      ]
     },
     "execution_count": 49,
     "metadata": {},
     "output_type": "execute_result"
    }
   ],
   "source": [
    "masks = masks[..., np.newaxis]\n",
    "masks.shape\n"
   ]
  },
  {
   "cell_type": "code",
   "execution_count": 50,
   "metadata": {},
   "outputs": [],
   "source": [
    "# Assuming your images and masks are numpy arrays\n",
    "# masks = masks[..., np.newaxis]  # add a channel dimension if necessary\n",
    "\n",
    "images_dataset = tf.data.Dataset.from_tensor_slices(images)\n",
    "masks_dataset = tf.data.Dataset.from_tensor_slices(masks)\n",
    "\n",
    "def augment_data(image, mask):\n",
    "    # Random rotation\n",
    "    rotation_angle = tf.random.uniform(shape=[], minval=-10, maxval=10, dtype=tf.float32)\n",
    "    image = tf.image.rot90(image, tf.cast(rotation_angle / 90, tf.int32))\n",
    "    mask = tf.image.rot90(mask, tf.cast(rotation_angle / 90, tf.int32))\n",
    "\n",
    "    # Random horizontal flip\n",
    "    if tf.random.uniform(shape=[], dtype=tf.float32) > 0.5:\n",
    "        image = tf.image.flip_left_right(image)\n",
    "        mask = tf.image.flip_left_right(mask)\n",
    "\n",
    "    return image, mask\n",
    "\n",
    "augmented_dataset = tf.data.Dataset.zip((images_dataset, masks_dataset))\n",
    "augmented_dataset = augmented_dataset.map(augment_data, num_parallel_calls=tf.data.AUTOTUNE)\n",
    "\n",
    "augmented_dataset = augmented_dataset.shuffle(1000)\n",
    "\n",
    "BATCH_SIZE = 32\n",
    "augmented_dataset = augmented_dataset.batch(BATCH_SIZE)\n",
    "augmented_dataset = augmented_dataset.prefetch(tf.data.AUTOTUNE)"
   ]
  },
  {
   "cell_type": "code",
   "execution_count": 51,
   "metadata": {},
   "outputs": [],
   "source": [
    "# Define the ModelCheckpoint callback to save weights at each epoch\n",
    "checkpoint_callback = tf.keras.callbacks.ModelCheckpoint(\n",
    "    filepath='checkpoints/unet_640x1132_epoch_{epoch:02d}.keras',\n",
    "    save_weights_only=False,\n",
    "    save_best_only=False,\n",
    "    save_freq='epoch'\n",
    ")\n",
    "os.makedirs('checkpoints', exist_ok=True)\n"
   ]
  },
  {
   "cell_type": "code",
   "execution_count": 52,
   "metadata": {},
   "outputs": [
    {
     "name": "stdout",
     "output_type": "stream",
     "text": [
      "Epoch 1/50\n"
     ]
    },
    {
     "name": "stderr",
     "output_type": "stream",
     "text": [
      "2024-06-18 10:37:00.290981: I external/local_xla/xla/stream_executor/cuda/cuda_dnn.cc:465] Loaded cuDNN version 8907\n",
      "2024-06-18 10:37:02.970737: W external/local_tsl/tsl/framework/bfc_allocator.cc:296] Allocator (GPU_0_bfc) ran out of memory trying to allocate 516.00MiB with freed_by_count=0. The caller indicates that this is not a failure, but this may mean that there could be performance gains if more memory were available.\n",
      "2024-06-18 10:37:03.082666: W tensorflow/core/framework/op_kernel.cc:1839] OP_REQUIRES failed at xla_ops.cc:580 : UNKNOWN: Failed to determine best cudnn convolution algorithm for:\n",
      "%cudnn-conv.135 = (f32[32,32,400,320]{3,2,1,0}, u8[0]{0}) custom-call(f32[32,3,801,641]{3,2,1,0} %transpose.964, f32[32,3,3,3]{3,2,1,0} %transpose.965), window={size=3x3 stride=2x2}, dim_labels=bf01_oi01->bf01, custom_call_target=\"__cudnn$convForward\", metadata={op_type=\"Conv2D\" op_name=\"functional_13_1/Conv1_1/convolution\" source_file=\"/home/apfox/anaconda3/lib/python3.11/site-packages/tensorflow/python/framework/ops.py\" source_line=1177}, backend_config={\"operation_queue_id\":\"0\",\"wait_on_operation_queues\":[],\"cudnn_conv_backend_config\":{\"conv_result_scale\":1,\"activation_mode\":\"kNone\",\"side_input_scale\":0,\"leakyrelu_alpha\":0}}\n",
      "\n",
      "Original error: RESOURCE_EXHAUSTED: Out of memory while trying to allocate 541065216 bytes.\n",
      "\n",
      "To ignore this failure and try to use a fallback algorithm (which may have suboptimal performance), use XLA_FLAGS=--xla_gpu_strict_conv_algorithm_picker=false.  Please also file a bug for the root cause of failing autotuning.\n",
      "2024-06-18 10:37:03.085692: W tensorflow/core/framework/local_rendezvous.cc:404] Local rendezvous is aborting with status: UNKNOWN: Failed to determine best cudnn convolution algorithm for:\n",
      "%cudnn-conv.135 = (f32[32,32,400,320]{3,2,1,0}, u8[0]{0}) custom-call(f32[32,3,801,641]{3,2,1,0} %transpose.964, f32[32,3,3,3]{3,2,1,0} %transpose.965), window={size=3x3 stride=2x2}, dim_labels=bf01_oi01->bf01, custom_call_target=\"__cudnn$convForward\", metadata={op_type=\"Conv2D\" op_name=\"functional_13_1/Conv1_1/convolution\" source_file=\"/home/apfox/anaconda3/lib/python3.11/site-packages/tensorflow/python/framework/ops.py\" source_line=1177}, backend_config={\"operation_queue_id\":\"0\",\"wait_on_operation_queues\":[],\"cudnn_conv_backend_config\":{\"conv_result_scale\":1,\"activation_mode\":\"kNone\",\"side_input_scale\":0,\"leakyrelu_alpha\":0}}\n",
      "\n",
      "Original error: RESOURCE_EXHAUSTED: Out of memory while trying to allocate 541065216 bytes.\n",
      "\n",
      "To ignore this failure and try to use a fallback algorithm (which may have suboptimal performance), use XLA_FLAGS=--xla_gpu_strict_conv_algorithm_picker=false.  Please also file a bug for the root cause of failing autotuning.\n",
      "\t [[{{node StatefulPartitionedCall}}]]\n"
     ]
    },
    {
     "ename": "UnknownError",
     "evalue": "Graph execution error:\n\nDetected at node StatefulPartitionedCall defined at (most recent call last):\n  File \"<frozen runpy>\", line 198, in _run_module_as_main\n\n  File \"<frozen runpy>\", line 88, in _run_code\n\n  File \"/home/apfox/anaconda3/lib/python3.11/site-packages/ipykernel_launcher.py\", line 17, in <module>\n\n  File \"/home/apfox/anaconda3/lib/python3.11/site-packages/traitlets/config/application.py\", line 992, in launch_instance\n\n  File \"/home/apfox/anaconda3/lib/python3.11/site-packages/ipykernel/kernelapp.py\", line 701, in start\n\n  File \"/home/apfox/anaconda3/lib/python3.11/site-packages/tornado/platform/asyncio.py\", line 195, in start\n\n  File \"/home/apfox/anaconda3/lib/python3.11/asyncio/base_events.py\", line 607, in run_forever\n\n  File \"/home/apfox/anaconda3/lib/python3.11/asyncio/base_events.py\", line 1922, in _run_once\n\n  File \"/home/apfox/anaconda3/lib/python3.11/asyncio/events.py\", line 80, in _run\n\n  File \"/home/apfox/anaconda3/lib/python3.11/site-packages/ipykernel/kernelbase.py\", line 534, in dispatch_queue\n\n  File \"/home/apfox/anaconda3/lib/python3.11/site-packages/ipykernel/kernelbase.py\", line 523, in process_one\n\n  File \"/home/apfox/anaconda3/lib/python3.11/site-packages/ipykernel/kernelbase.py\", line 429, in dispatch_shell\n\n  File \"/home/apfox/anaconda3/lib/python3.11/site-packages/ipykernel/kernelbase.py\", line 767, in execute_request\n\n  File \"/home/apfox/anaconda3/lib/python3.11/site-packages/ipykernel/ipkernel.py\", line 429, in do_execute\n\n  File \"/home/apfox/anaconda3/lib/python3.11/site-packages/ipykernel/zmqshell.py\", line 549, in run_cell\n\n  File \"/home/apfox/anaconda3/lib/python3.11/site-packages/IPython/core/interactiveshell.py\", line 3051, in run_cell\n\n  File \"/home/apfox/anaconda3/lib/python3.11/site-packages/IPython/core/interactiveshell.py\", line 3106, in _run_cell\n\n  File \"/home/apfox/anaconda3/lib/python3.11/site-packages/IPython/core/async_helpers.py\", line 129, in _pseudo_sync_runner\n\n  File \"/home/apfox/anaconda3/lib/python3.11/site-packages/IPython/core/interactiveshell.py\", line 3311, in run_cell_async\n\n  File \"/home/apfox/anaconda3/lib/python3.11/site-packages/IPython/core/interactiveshell.py\", line 3493, in run_ast_nodes\n\n  File \"/home/apfox/anaconda3/lib/python3.11/site-packages/IPython/core/interactiveshell.py\", line 3553, in run_code\n\n  File \"/tmp/ipykernel_160003/2695611729.py\", line 9, in <module>\n\n  File \"/home/apfox/anaconda3/lib/python3.11/site-packages/keras/src/utils/traceback_utils.py\", line 117, in error_handler\n\n  File \"/home/apfox/anaconda3/lib/python3.11/site-packages/keras/src/backend/tensorflow/trainer.py\", line 314, in fit\n\n  File \"/home/apfox/anaconda3/lib/python3.11/site-packages/keras/src/backend/tensorflow/trainer.py\", line 117, in one_step_on_iterator\n\nFailed to determine best cudnn convolution algorithm for:\n%cudnn-conv.135 = (f32[32,32,400,320]{3,2,1,0}, u8[0]{0}) custom-call(f32[32,3,801,641]{3,2,1,0} %transpose.964, f32[32,3,3,3]{3,2,1,0} %transpose.965), window={size=3x3 stride=2x2}, dim_labels=bf01_oi01->bf01, custom_call_target=\"__cudnn$convForward\", metadata={op_type=\"Conv2D\" op_name=\"functional_13_1/Conv1_1/convolution\" source_file=\"/home/apfox/anaconda3/lib/python3.11/site-packages/tensorflow/python/framework/ops.py\" source_line=1177}, backend_config={\"operation_queue_id\":\"0\",\"wait_on_operation_queues\":[],\"cudnn_conv_backend_config\":{\"conv_result_scale\":1,\"activation_mode\":\"kNone\",\"side_input_scale\":0,\"leakyrelu_alpha\":0}}\n\nOriginal error: RESOURCE_EXHAUSTED: Out of memory while trying to allocate 541065216 bytes.\n\nTo ignore this failure and try to use a fallback algorithm (which may have suboptimal performance), use XLA_FLAGS=--xla_gpu_strict_conv_algorithm_picker=false.  Please also file a bug for the root cause of failing autotuning.\n\t [[{{node StatefulPartitionedCall}}]] [Op:__inference_one_step_on_iterator_156067]",
     "output_type": "error",
     "traceback": [
      "\u001b[0;31m---------------------------------------------------------------------------\u001b[0m",
      "\u001b[0;31mUnknownError\u001b[0m                              Traceback (most recent call last)",
      "Cell \u001b[0;32mIn[52], line 9\u001b[0m\n\u001b[1;32m      2\u001b[0m \u001b[38;5;28;01mfrom\u001b[39;00m \u001b[38;5;21;01mtensorflow\u001b[39;00m\u001b[38;5;21;01m.\u001b[39;00m\u001b[38;5;21;01mkeras\u001b[39;00m\u001b[38;5;21;01m.\u001b[39;00m\u001b[38;5;21;01moptimizers\u001b[39;00m \u001b[38;5;28;01mimport\u001b[39;00m Adam\n\u001b[1;32m      4\u001b[0m model\u001b[38;5;241m.\u001b[39mcompile(optimizer\u001b[38;5;241m=\u001b[39mAdam(learning_rate\u001b[38;5;241m=\u001b[39m\u001b[38;5;241m0.001\u001b[39m),\n\u001b[1;32m      5\u001b[0m               loss\u001b[38;5;241m=\u001b[39m\u001b[38;5;124m'\u001b[39m\u001b[38;5;124mbinary_crossentropy\u001b[39m\u001b[38;5;124m'\u001b[39m,\n\u001b[1;32m      6\u001b[0m               metrics\u001b[38;5;241m=\u001b[39m[\u001b[38;5;124m'\u001b[39m\u001b[38;5;124maccuracy\u001b[39m\u001b[38;5;124m'\u001b[39m])\n\u001b[0;32m----> 9\u001b[0m model\u001b[38;5;241m.\u001b[39mfit(augmented_dataset, epochs\u001b[38;5;241m=\u001b[39m\u001b[38;5;241m50\u001b[39m, callbacks\u001b[38;5;241m=\u001b[39m[checkpoint_callback], verbose\u001b[38;5;241m=\u001b[39m\u001b[38;5;241m1\u001b[39m)\n",
      "File \u001b[0;32m~/anaconda3/lib/python3.11/site-packages/keras/src/utils/traceback_utils.py:122\u001b[0m, in \u001b[0;36mfilter_traceback.<locals>.error_handler\u001b[0;34m(*args, **kwargs)\u001b[0m\n\u001b[1;32m    119\u001b[0m     filtered_tb \u001b[38;5;241m=\u001b[39m _process_traceback_frames(e\u001b[38;5;241m.\u001b[39m__traceback__)\n\u001b[1;32m    120\u001b[0m     \u001b[38;5;66;03m# To get the full stack trace, call:\u001b[39;00m\n\u001b[1;32m    121\u001b[0m     \u001b[38;5;66;03m# `keras.config.disable_traceback_filtering()`\u001b[39;00m\n\u001b[0;32m--> 122\u001b[0m     \u001b[38;5;28;01mraise\u001b[39;00m e\u001b[38;5;241m.\u001b[39mwith_traceback(filtered_tb) \u001b[38;5;28;01mfrom\u001b[39;00m \u001b[38;5;28;01mNone\u001b[39;00m\n\u001b[1;32m    123\u001b[0m \u001b[38;5;28;01mfinally\u001b[39;00m:\n\u001b[1;32m    124\u001b[0m     \u001b[38;5;28;01mdel\u001b[39;00m filtered_tb\n",
      "File \u001b[0;32m~/anaconda3/lib/python3.11/site-packages/tensorflow/python/eager/execute.py:53\u001b[0m, in \u001b[0;36mquick_execute\u001b[0;34m(op_name, num_outputs, inputs, attrs, ctx, name)\u001b[0m\n\u001b[1;32m     51\u001b[0m \u001b[38;5;28;01mtry\u001b[39;00m:\n\u001b[1;32m     52\u001b[0m   ctx\u001b[38;5;241m.\u001b[39mensure_initialized()\n\u001b[0;32m---> 53\u001b[0m   tensors \u001b[38;5;241m=\u001b[39m pywrap_tfe\u001b[38;5;241m.\u001b[39mTFE_Py_Execute(ctx\u001b[38;5;241m.\u001b[39m_handle, device_name, op_name,\n\u001b[1;32m     54\u001b[0m                                       inputs, attrs, num_outputs)\n\u001b[1;32m     55\u001b[0m \u001b[38;5;28;01mexcept\u001b[39;00m core\u001b[38;5;241m.\u001b[39m_NotOkStatusException \u001b[38;5;28;01mas\u001b[39;00m e:\n\u001b[1;32m     56\u001b[0m   \u001b[38;5;28;01mif\u001b[39;00m name \u001b[38;5;129;01mis\u001b[39;00m \u001b[38;5;129;01mnot\u001b[39;00m \u001b[38;5;28;01mNone\u001b[39;00m:\n",
      "\u001b[0;31mUnknownError\u001b[0m: Graph execution error:\n\nDetected at node StatefulPartitionedCall defined at (most recent call last):\n  File \"<frozen runpy>\", line 198, in _run_module_as_main\n\n  File \"<frozen runpy>\", line 88, in _run_code\n\n  File \"/home/apfox/anaconda3/lib/python3.11/site-packages/ipykernel_launcher.py\", line 17, in <module>\n\n  File \"/home/apfox/anaconda3/lib/python3.11/site-packages/traitlets/config/application.py\", line 992, in launch_instance\n\n  File \"/home/apfox/anaconda3/lib/python3.11/site-packages/ipykernel/kernelapp.py\", line 701, in start\n\n  File \"/home/apfox/anaconda3/lib/python3.11/site-packages/tornado/platform/asyncio.py\", line 195, in start\n\n  File \"/home/apfox/anaconda3/lib/python3.11/asyncio/base_events.py\", line 607, in run_forever\n\n  File \"/home/apfox/anaconda3/lib/python3.11/asyncio/base_events.py\", line 1922, in _run_once\n\n  File \"/home/apfox/anaconda3/lib/python3.11/asyncio/events.py\", line 80, in _run\n\n  File \"/home/apfox/anaconda3/lib/python3.11/site-packages/ipykernel/kernelbase.py\", line 534, in dispatch_queue\n\n  File \"/home/apfox/anaconda3/lib/python3.11/site-packages/ipykernel/kernelbase.py\", line 523, in process_one\n\n  File \"/home/apfox/anaconda3/lib/python3.11/site-packages/ipykernel/kernelbase.py\", line 429, in dispatch_shell\n\n  File \"/home/apfox/anaconda3/lib/python3.11/site-packages/ipykernel/kernelbase.py\", line 767, in execute_request\n\n  File \"/home/apfox/anaconda3/lib/python3.11/site-packages/ipykernel/ipkernel.py\", line 429, in do_execute\n\n  File \"/home/apfox/anaconda3/lib/python3.11/site-packages/ipykernel/zmqshell.py\", line 549, in run_cell\n\n  File \"/home/apfox/anaconda3/lib/python3.11/site-packages/IPython/core/interactiveshell.py\", line 3051, in run_cell\n\n  File \"/home/apfox/anaconda3/lib/python3.11/site-packages/IPython/core/interactiveshell.py\", line 3106, in _run_cell\n\n  File \"/home/apfox/anaconda3/lib/python3.11/site-packages/IPython/core/async_helpers.py\", line 129, in _pseudo_sync_runner\n\n  File \"/home/apfox/anaconda3/lib/python3.11/site-packages/IPython/core/interactiveshell.py\", line 3311, in run_cell_async\n\n  File \"/home/apfox/anaconda3/lib/python3.11/site-packages/IPython/core/interactiveshell.py\", line 3493, in run_ast_nodes\n\n  File \"/home/apfox/anaconda3/lib/python3.11/site-packages/IPython/core/interactiveshell.py\", line 3553, in run_code\n\n  File \"/tmp/ipykernel_160003/2695611729.py\", line 9, in <module>\n\n  File \"/home/apfox/anaconda3/lib/python3.11/site-packages/keras/src/utils/traceback_utils.py\", line 117, in error_handler\n\n  File \"/home/apfox/anaconda3/lib/python3.11/site-packages/keras/src/backend/tensorflow/trainer.py\", line 314, in fit\n\n  File \"/home/apfox/anaconda3/lib/python3.11/site-packages/keras/src/backend/tensorflow/trainer.py\", line 117, in one_step_on_iterator\n\nFailed to determine best cudnn convolution algorithm for:\n%cudnn-conv.135 = (f32[32,32,400,320]{3,2,1,0}, u8[0]{0}) custom-call(f32[32,3,801,641]{3,2,1,0} %transpose.964, f32[32,3,3,3]{3,2,1,0} %transpose.965), window={size=3x3 stride=2x2}, dim_labels=bf01_oi01->bf01, custom_call_target=\"__cudnn$convForward\", metadata={op_type=\"Conv2D\" op_name=\"functional_13_1/Conv1_1/convolution\" source_file=\"/home/apfox/anaconda3/lib/python3.11/site-packages/tensorflow/python/framework/ops.py\" source_line=1177}, backend_config={\"operation_queue_id\":\"0\",\"wait_on_operation_queues\":[],\"cudnn_conv_backend_config\":{\"conv_result_scale\":1,\"activation_mode\":\"kNone\",\"side_input_scale\":0,\"leakyrelu_alpha\":0}}\n\nOriginal error: RESOURCE_EXHAUSTED: Out of memory while trying to allocate 541065216 bytes.\n\nTo ignore this failure and try to use a fallback algorithm (which may have suboptimal performance), use XLA_FLAGS=--xla_gpu_strict_conv_algorithm_picker=false.  Please also file a bug for the root cause of failing autotuning.\n\t [[{{node StatefulPartitionedCall}}]] [Op:__inference_one_step_on_iterator_156067]"
     ]
    }
   ],
   "source": [
    "#fit the model\n",
    "from tensorflow.keras.optimizers import Adam\n",
    "\n",
    "model.compile(optimizer=Adam(learning_rate=0.001),\n",
    "              loss='binary_crossentropy',\n",
    "              metrics=['accuracy'])\n",
    "\n",
    "\n",
    "model.fit(augmented_dataset, epochs=50, callbacks=[checkpoint_callback], verbose=1)"
   ]
  }
 ],
 "metadata": {
  "kernelspec": {
   "display_name": "base",
   "language": "python",
   "name": "python3"
  },
  "language_info": {
   "codemirror_mode": {
    "name": "ipython",
    "version": 3
   },
   "file_extension": ".py",
   "mimetype": "text/x-python",
   "name": "python",
   "nbconvert_exporter": "python",
   "pygments_lexer": "ipython3",
   "version": "3.11.7"
  }
 },
 "nbformat": 4,
 "nbformat_minor": 2
}
